logging was configured successfully
2021-12-14 15:41:24,141:INFO:superset.utils.logging_configurator:logging was configured successfully
2021-12-14 15:41:24,168:INFO:root:Configured event logger of type <class 'superset.utils.log.DBEventLogger'>
/usr/local/lib/python3.8/site-packages/flask_caching/__init__.py:201: UserWarning: Flask-Caching: CACHE_TYPE is set to null, caching is effectively disabled.
  warnings.warn(
No PIL installation found
2021-12-14 15:41:24,741:INFO:superset.utils.screenshots:No PIL installation found
 * Serving Flask app "superset.app:create_app()" (lazy loading)
 * Environment: development
 * Debug mode: on
Traceback (most recent call last):
  File "/usr/local/bin/superset", line 33, in <module>
    sys.exit(load_entry_point('apache-superset', 'console_scripts', 'superset')())
  File "/usr/local/lib/python3.8/site-packages/click/core.py", line 829, in __call__
    return self.main(*args, **kwargs)
  File "/usr/local/lib/python3.8/site-packages/flask/cli.py", line 586, in main
    return super(FlaskGroup, self).main(*args, **kwargs)
  File "/usr/local/lib/python3.8/site-packages/click/core.py", line 782, in main
    rv = self.invoke(ctx)
  File "/usr/local/lib/python3.8/site-packages/click/core.py", line 1259, in invoke
    return _process_result(sub_ctx.command.invoke(sub_ctx))
  File "/usr/local/lib/python3.8/site-packages/click/core.py", line 1066, in invoke
    return ctx.invoke(self.callback, **ctx.params)
  File "/usr/local/lib/python3.8/site-packages/click/core.py", line 610, in invoke
    return callback(*args, **kwargs)
  File "/usr/local/lib/python3.8/site-packages/click/decorators.py", line 73, in new_func
    return ctx.invoke(f, obj, *args, **kwargs)
  File "/usr/local/lib/python3.8/site-packages/click/core.py", line 610, in invoke
    return callback(*args, **kwargs)
  File "/usr/local/lib/python3.8/site-packages/flask/cli.py", line 852, in run_command
    run_simple(
  File "/usr/local/lib/python3.8/site-packages/werkzeug/serving.py", line 1030, in run_simple
    s.bind(server_address)
OSError: [Errno 98] Address already in use
